<mujoco model="H2Loop">
  <compiler angle="radian" />
  <default>
    <joint damping="0.05" armature="0.01" frictionloss="0.2" />
  </default>
  <asset>
    <mesh name="pelvis" content_type="model/stl" file="meshes/pelvis.stl" />
    <mesh name="left_hip_pitch_link" content_type="model/stl" file="meshes/left_hip_pitch_link.stl" />
    <mesh name="left_hip_roll_link" content_type="model/stl" file="meshes/left_hip_roll_link.stl" />
    <mesh name="left_hip_yaw_link" content_type="model/stl" file="meshes/left_hip_yaw_link.stl" />
    <mesh name="left_knee_link" content_type="model/stl" file="meshes/left_knee_link.stl" />
    <mesh name="left_ankle_roll_link" content_type="model/stl" file="meshes/left_ankle_roll_link.stl" />
    <mesh name="left_ankle_pitch_link" content_type="model/stl" file="meshes/left_ankle_pitch_link.stl" />
    <mesh name="right_hip_pitch_link" content_type="model/stl" file="meshes/right_hip_pitch_link.stl" />
    <mesh name="right_hip_roll_link" content_type="model/stl" file="meshes/right_hip_roll_link.stl" />
    <mesh name="right_hip_yaw_link" content_type="model/stl" file="meshes/right_hip_yaw_link.stl" />
    <mesh name="right_knee_link" content_type="model/stl" file="meshes/right_knee_link.stl" />
    <mesh name="right_ankle_roll_link" content_type="model/stl" file="meshes/right_ankle_roll_link.stl" />
    <mesh name="right_ankle_pitch_link" content_type="model/stl" file="meshes/right_ankle_pitch_link.stl" />
    <mesh name="waist_yaw_link" content_type="model/stl" file="meshes/waist_yaw_link.stl" />
    <mesh name="waist_roll_link" content_type="model/stl" file="meshes/waist_roll_link.stl" />
    <mesh name="torso_link" content_type="model/stl" file="meshes/torso_link.stl" />
    <mesh name="head_pitch_link" content_type="model/stl" file="meshes/head_pitch_link.stl" />
    <mesh name="head_yaw_link" content_type="model/stl" file="meshes/head_yaw_link.stl" />
    <mesh name="left_shoulder_pitch_link" content_type="model/stl" file="meshes/left_shoulder_pitch_link.stl" />
    <mesh name="left_shoulder_roll_link" content_type="model/stl" file="meshes/left_shoulder_roll_link.stl" />
    <mesh name="left_shoulder_yaw_link" content_type="model/stl" file="meshes/left_shoulder_yaw_link.stl" />
    <mesh name="left_elbow_link" content_type="model/stl" file="meshes/left_elbow_link.stl" />
    <mesh name="left_wrist_roll_link" content_type="model/stl" file="meshes/left_wrist_roll_link.stl" />
    <mesh name="left_wrist_pitch_link" content_type="model/stl" file="meshes/left_wrist_pitch_link.stl" />
    <mesh name="left_wrist_yaw_link" content_type="model/stl" file="meshes/left_wrist_yaw_link.stl" />
    <mesh name="left_hand_link" content_type="model/stl" file="meshes/left_hand_link.stl" />
    <mesh name="right_shoulder_pitch_link" content_type="model/stl" file="meshes/right_shoulder_pitch_link.stl" />
    <mesh name="right_shoulder_roll_link" content_type="model/stl" file="meshes/right_shoulder_roll_link.stl" />
    <mesh name="right_shoulder_yaw_link" content_type="model/stl" file="meshes/right_shoulder_yaw_link.stl" />
    <mesh name="right_elbow_link" content_type="model/stl" file="meshes/right_elbow_link.stl" />
    <mesh name="right_wrist_roll_link" content_type="model/stl" file="meshes/right_wrist_roll_link.stl" />
    <mesh name="right_wrist_pitch_link" content_type="model/stl" file="meshes/right_wrist_pitch_link.stl" />
    <mesh name="right_wrist_yaw_link" content_type="model/stl" file="meshes/right_wrist_yaw_link.stl" />
    <mesh name="right_hand_link" content_type="model/stl" file="meshes/right_hand_link.stl" />
    <mesh name="left_ankle_A_link" content_type="model/stl" file="meshes/left_ankle_A_link.STL" />
    <mesh name="right_ankle_A_link" content_type="model/stl" file="meshes/right_ankle_A_link.STL" />
    <mesh name="Link-pitch-R-A3" content_type="model/stl" file="meshes/Link-pitch-R-A3.STL" />
    <mesh name="Link-pitch-L-A3" content_type="model/stl" file="meshes/Link-pitch-L-A3.STL" />
  </asset>
  <worldbody>
    <body name="pelvis" pos="0 0 1.11">
      <inertial pos="0.00027091 -0.00003310 -0.01452551" mass="8.5477" fullinertia="0.03527375 0.02269029 0.02723664 -0.00014759 0.00011770 0.00000842" />
      <freejoint name="floating_base_joint" />
      <geom type="mesh" contype="0" conaffinity="0" group="1" density="0" rgba="0.7 0.7 0.7 1" mesh="pelvis" />
      <geom type="mesh" rgba="0.7 0.7 0.7 1" mesh="pelvis" />
      <body name="left_hip_pitch_link" pos="0 0.08038 -0.046407" quat="0.965926 -0.25882 0 0">
        <inertial pos="0.00294368 0.061102 -0.017351" quat="0.89044 0.453883 -0.0133707 -0.0304704" mass="2.8737" diaginertia="0.00537408 0.00421163 0.0036878" />
        <joint name="left_hip_pitch_joint" pos="0 0 0" axis="0 1 0" range="-2.4526 2.77542" actuatorfrcrange="-360 360" />
        <geom type="mesh" contype="0" conaffinity="0" group="1" density="0" rgba="0.4 0.4 0.4 1" mesh="left_hip_pitch_link" />
        <body name="left_hip_roll_link" pos="0.041774 0.0635 -0.019" quat="0.965926 0.25882 0 0">
          <inertial pos="-0.0175789 -0.00607425 -0.041315" quat="-0.165515 0.598251 -0.0524355 0.782273" mass="0.785079" diaginertia="0.0023778 0.00200443 0.0015153" />
          <joint name="left_hip_roll_joint" pos="0 0 0" axis="1 0 0" range="-0.467441 2.16886" actuatorfrcrange="-360 360" />
          <geom type="mesh" contype="0" conaffinity="0" group="1" density="0" rgba="0.7 0.7 0.7 1" mesh="left_hip_roll_link" />
          <geom size="0.05" pos="-0.02 0 0" rgba="0.7 0.7 0.7 1" />
          <body name="left_hip_yaw_link" pos="-0.028187 -0.0095 -0.0737">
            <inertial pos="0.00069408 -0.0108659 -0.113015" quat="0.621956 -0.0405938 0.0198649 0.781747" mass="7.0875" diaginertia="0.0514013 0.0505964 0.0130063" />
            <joint name="left_hip_yaw_joint" pos="0 0 0" axis="0 0 1" range="-2.827 2.827" actuatorfrcrange="-360 360" />
            <geom type="mesh" contype="0" conaffinity="0" group="1" density="0" rgba="0.7 0.7 0.7 0.3" mesh="left_hip_yaw_link" />
            <geom type="mesh" rgba="0.7 0.7 0.7 0.3" mesh="left_hip_yaw_link" />
            <body name="left_knee_link" pos="-0.010308 0.022549 -0.31959">
              <inertial pos="0.00461561 -0.0225438 -0.167109" quat="0.689161 0.00323499 0.00294956 0.724595" mass="4.3544" diaginertia="0.0512786 0.0511286 0.00334066" />
              <joint name="left_knee_joint" pos="0 0 0" axis="0 1 0" range="-0.08725 2.53025" actuatorfrcrange="-360 360" />
              <geom type="mesh" contype="0" conaffinity="0" group="1" density="0" rgba="0.7 0.7 0.7 0.3" mesh="left_knee_link" />
              <geom size="0.025 0.175" pos="0.01 -0.022549 -0.25" type="cylinder" rgba="0.7 0.7 0.7 0.3" />
              <geom size="0.005" pos="0.014618 0 0.031799" contype="0" conaffinity="0" group="1" density="0" rgba="0 0 1 1" />
              <body name="left_ankle_roll_link" pos="0.032719 -0.023002 -0.49662">
                <inertial pos="-0.0174063 6.424e-05 -0.0002146" quat="0.499157 0.502573 -0.497809 0.500449" mass="0.123182" diaginertia="4.00501e-05 3.43207e-05 1.44993e-05" />
                <joint name="left_ankle_roll_joint" pos="0 0 0" axis="1 0 0" range="-0.349066 0.296706" actuatorfrcrange="-19 19" />
                <geom type="mesh" contype="0" conaffinity="0" group="1" density="0" rgba="0.7 0.7 0.7 1" mesh="left_ankle_roll_link" />
                <body name="left_ankle_pitch_link" pos="-0.014516 -0.0373 0">
                  <inertial pos="0.0319785 0.0370056 -0.0287879" quat="5.23621e-05 0.72367 -4.43674e-05 0.690147" mass="0.895967" diaginertia="0.0043887 0.00411623 0.000601146" />
                  <joint name="left_ankle_pitch_joint" pos="0 0 0" axis="0 1 0" range="-1.13446 0.610865" actuatorfrcrange="-66.88 66.88" />
                  <geom type="mesh" contype="0" conaffinity="0" group="1" density="0" rgba="0.4 0.4 0.4 1" mesh="left_ankle_pitch_link" />
                  <geom type="mesh" rgba="0.4 0.4 0.4 1" mesh="left_ankle_pitch_link" />
                  <geom size="0.005" pos="-0.04003 0.0373 0.0073" contype="0" conaffinity="0" group="1" density="0" rgba="0 1 0 1" />
                </body>
              </body>
              <body name="left_ankle_A_link" pos="0.00098998 0.02225 -0.12689">
                <inertial pos="0.0132403 -0.0415689 0.00193978" quat="0.459412 0.524788 0.547363 0.462528" mass="0.0646149" diaginertia="3.19082e-05 2.38904e-05 1.28987e-05" />
                <joint name="left_ankle_A_joint" pos="0 0 0" axis="0 1 0" range="-1 2" actuatorfrcrange="-105.6 105.6" />
                <geom type="mesh" contype="0" conaffinity="0" group="1" density="0" rgba="0.898039 0.917647 0.929412 0.2" mesh="left_ankle_A_link" />
                <geom type="mesh" rgba="0.898039 0.917647 0.929412 0.2" mesh="left_ankle_A_link" />
                <geom size="0.005" pos="0.036796 -0.045252 0.0038791" contype="0" conaffinity="0" group="1" density="0" rgba="0 1 0 1" />
                <body name="left_ankle_loop_rod" pos="0.036796 -0.045252 0.0038791">
                  <inertial pos="0 0 0" mass="0.001" diaginertia="1e-7 1e-7 1e-7" />
                  <joint name="left_ankle_loop_rod_joint" type="ball" damping="0.1" />
                  <geom type="capsule" fromto="0 0 0 -0.05961298 0 -0.3663091" size="0.003" contype="0" conaffinity="0" group="1" density="0" rgba="0.1 0.1 0.1 0.5" />
                </body>
              </body>
            </body>
            <body name="left_knee_motor_link" pos="0.002489 0.022549 -0.147841">
              <inertial pos="0.007259 0 0.015919" quat="0.977207 0 0.212287 0" mass="0.002" diaginertia="8.12215e-07 8.12215e-07 2e-07" />
              <joint name="left_knee_motor_joint" pos="0 0 0" axis="0 1 0" range="-0.2 2.9" actuatorfrcrange="-360 360" />
              <geom size="0.005" pos="0.014518 0 0.031838" contype="0" conaffinity="0" group="1" density="0" rgba="0 0 1 1" />
              <body name="left_knee_loop_rod" pos="0.014518 0 0.031838">
                <inertial pos="0 0 0" mass="0.001" diaginertia="1e-7 1e-7 1e-7" />
                <joint name="left_knee_loop_rod_joint" type="ball" damping="0.1" />
                <geom type="capsule" fromto="0 0 0 -0.012697 0 -0.171788" size="0.003" contype="0" conaffinity="0" group="1" density="0" rgba="0.1 0.1 0.1 0.5" />
              </body>
            </body>
          </body>
        </body>
      </body>
      <body name="right_hip_pitch_link" pos="0 -0.08038 -0.046407" quat="0.965926 0.25882 0 0">
        <inertial pos="0.00294368 -0.061102 -0.017351" quat="0.453883 0.89044 0.0304704 0.0133707" mass="2.8737" diaginertia="0.00537408 0.00421163 0.0036878" />
        <joint name="right_hip_pitch_joint" pos="0 0 0" axis="0 1 0" range="-2.4526 2.77542" actuatorfrcrange="-360 360" />
        <geom type="mesh" contype="0" conaffinity="0" group="1" density="0" rgba="0.4 0.4 0.4 1" mesh="right_hip_pitch_link" />
        <body name="right_hip_roll_link" pos="0.041774 -0.0635 -0.019" quat="0.965926 -0.25882 0 0">
          <inertial pos="-0.0175789 0.00607425 -0.041315" quat="0.165515 0.598251 0.0524355 0.782273" mass="0.75122" diaginertia="0.0023778 0.00200443 0.0015153" />
          <joint name="right_hip_roll_joint" pos="0 0 0" axis="1 0 0" range="-2.16886 0.467441" actuatorfrcrange="-360 360" />
          <geom type="mesh" contype="0" conaffinity="0" group="1" density="0" rgba="0.7 0.7 0.7 1" mesh="right_hip_roll_link" />
          <geom size="0.05" pos="-0.038 0 0" rgba="0.7 0.7 0.7 1" />
          <body name="right_hip_yaw_link" pos="-0.028187 0.0095 -0.0737">
            <inertial pos="0.00069408 0.0108659 -0.113015" quat="0.781747 0.0198649 -0.0405938 0.621956" mass="7.0875" diaginertia="0.0514013 0.0505964 0.0130063" />
            <joint name="right_hip_yaw_joint" pos="0 0 0" axis="0 0 1" range="-2.827 2.827" actuatorfrcrange="-360 360" />
            <geom type="mesh" contype="0" conaffinity="0" group="1" density="0" rgba="0.7 0.7 0.7 0.3" mesh="right_hip_yaw_link" />
            <geom type="mesh" rgba="0.7 0.7 0.7 0.3" mesh="right_hip_yaw_link" />
            <body name="right_knee_link" pos="-0.010308 -0.022549 -0.31959">
              <inertial pos="0.00461561 0.0225438 -0.167109" quat="0.724595 0.00294956 0.00323499 0.689161" mass="4.3544" diaginertia="0.0512786 0.0511286 0.00334066" />
              <joint name="right_knee_joint" pos="0 0 0" axis="0 1 0" range="-0.08725 2.53025" actuatorfrcrange="-360 360" />
              <geom type="mesh" contype="0" conaffinity="0" group="1" density="0" rgba="0.7 0.7 0.7 0.3" mesh="right_knee_link" />
              <geom size="0.025 0.175" pos="0.01 0.022549 -0.25" type="cylinder" rgba="0.7 0.7 0.7 0.3" />
              <geom size="0.005" pos="0.014618 0 0.031799" contype="0" conaffinity="0" group="1" density="0" rgba="0 0 1 1" />
              <body name="right_ankle_roll_link" pos="0.032719 0.023002 -0.49662">
                <inertial pos="-0.0174063 -6.424e-05 -0.0002146" quat="0.502573 0.499157 -0.500449 0.497809" mass="0.123182" diaginertia="4.00501e-05 3.43207e-05 1.44993e-05" />
                <joint name="right_ankle_roll_joint" pos="0 0 0" axis="1 0 0" range="-0.296706 0.349066" actuatorfrcrange="-19 19" />
                <geom type="mesh" contype="0" conaffinity="0" group="1" density="0" rgba="0.7 0.7 0.7 1" mesh="right_ankle_roll_link" />
                <body name="right_ankle_pitch_link" pos="-0.014516 0.0373 0">
                  <inertial pos="0.0319785 -0.0370056 -0.0287879" quat="-5.23621e-05 0.72367 4.43674e-05 0.690147" mass="0.895967" diaginertia="0.0043887 0.00411623 0.000601146" />
                  <joint name="right_ankle_pitch_joint" pos="0 0 0" axis="0 1 0" range="-1.13446 0.610865" actuatorfrcrange="-66.88 66.88" />
                  <geom type="mesh" contype="0" conaffinity="0" group="1" density="0" rgba="0.4 0.4 0.4 1" mesh="right_ankle_pitch_link" />
                  <geom type="mesh" rgba="0.4 0.4 0.4 1" mesh="right_ankle_pitch_link" />
                  <geom size="0.005" pos="-0.04003 -0.0373 0.0073" contype="0" conaffinity="0" group="1" density="0" rgba="0 1 0 1" />
                </body>
              </body>
              <body name="right_ankle_A_link" pos="0.00098998 -0.02225 -0.12689">
                <inertial pos="0.0132403 0.0415689 0.00193978" quat="0.462528 0.547363 0.524788 0.459412" mass="0.0646149" diaginertia="3.19082e-05 2.38904e-05 1.28987e-05" />
                <joint name="right_ankle_A_joint" pos="0 0 0" axis="0 1 0" range="-1 2" actuatorfrcrange="-105.6 105.6" />
                <geom type="mesh" contype="0" conaffinity="0" group="1" density="0" rgba="0.898039 0.917647 0.929412 0.2" mesh="right_ankle_A_link" />
                <geom type="mesh" rgba="0.898039 0.917647 0.929412 0.2" mesh="right_ankle_A_link" />
                <geom size="0.005" pos="0.036796 0.045252 0.0038791" contype="0" conaffinity="0" group="1" density="0" rgba="0 1 0 1" />
                <body name="right_ankle_loop_rod" pos="0.036796 0.045252 0.0038791">
                  <inertial pos="0 0 0" mass="0.001" diaginertia="1e-7 1e-7 1e-7" />
                  <joint name="right_ankle_loop_rod_joint" type="ball" damping="0.1" />
                  <geom type="capsule" fromto="0 0 0 -0.05961298 0 -0.3663091" size="0.003" contype="0" conaffinity="0" group="1" density="0" rgba="0.1 0.1 0.1 0.5" />
                </body>
              </body>
            </body>
            <body name="right_knee_motor_link" pos="0.002489 -0.022549 -0.147841">
              <inertial pos="0.007259 0 0.015919" quat="0.977207 0 0.212287 0" mass="0.002" diaginertia="8.12215e-07 8.12215e-07 2e-07" />
              <joint name="right_knee_motor_joint" pos="0 0 0" axis="0 1 0" range="-0.2 2.9" actuatorfrcrange="-360 360" />
              <geom size="0.005" pos="0.014518 0 0.031838" contype="0" conaffinity="0" group="1" density="0" rgba="0 0 1 1" />
              <body name="right_knee_loop_rod" pos="0.014518 0 0.031838">
                <inertial pos="0 0 0" mass="0.001" diaginertia="1e-7 1e-7 1e-7" />
                <joint name="right_knee_loop_rod_joint" type="ball" damping="0.1" />
                <geom type="capsule" fromto="0 0 0 -0.012697 0 -0.171788" size="0.003" contype="0" conaffinity="0" group="1" density="0" rgba="0.1 0.1 0.1 0.5" />
              </body>
            </body>
          </body>
        </body>
      </body>
      <body name="waist_yaw_link" pos="0 0 0.090537">
        <inertial pos="0.00672958 -0.000199825 0.0174156" quat="-0.0033029 0.722794 -0.012129 0.690949" mass="0.315556" diaginertia="0.000343147 0.000288973 0.000124065" />
        <joint name="waist_yaw_joint" pos="0 0 0" axis="0 0 1" range="-1.7453 1.7453" actuatorfrcrange="-120 120" />
        <geom type="mesh" contype="0" conaffinity="0" group="1" density="0" rgba="0.7 0.7 0.7 1" mesh="waist_yaw_link" />
        <geom size="0.005" pos="0.0364243 -0.0237442 0.0209892" contype="0" conaffinity="0" group="1" density="0" rgba="0 0 1 1" />
        <geom size="0.005" pos="0.0360864 0.0242546 0.0209893" quat="0.999994 -5.23465e-07 0.000148712 0.00351996" contype="0" conaffinity="0" group="1" density="0" rgba="0 1 0 1" />
        <body name="waist_roll_link" pos="0 0 0.0325">
          <inertial pos="0 0.00061119 0" quat="0.5 0.5 -0.5 0.5" mass="0.138419" diaginertia="2.304e-05 1.668e-05 1.509e-05" />
          <joint name="waist_roll_joint" pos="0 0 0" axis="1 0 0" range="-0.5236 0.5236" actuatorfrcrange="-180 180" />
          <geom type="mesh" contype="0" conaffinity="0" group="1" density="0" rgba="0.7 0.7 0.7 1" mesh="waist_roll_link" />
          <body name="torso_link">
            <inertial pos="0.00740421 0.00628045 0.215575" quat="0.99932 -0.0321662 -0.00775231 0.0162839" mass="18.532" diaginertia="0.287321 0.26278 0.0934525" />
            <joint name="waist_pitch_joint" pos="0 0 0" axis="0 1 0" range="-0.43633 0.5236" actuatorfrcrange="-180 180" />
            <geom type="mesh" contype="0" conaffinity="0" group="1" density="0" rgba="0.7 0.7 0.7 0.3" mesh="torso_link" />
            <geom type="mesh" rgba="0.7 0.7 0.7 0.3" mesh="torso_link" />
            <body name="head_pitch_link" pos="-0.0001147 -0.0189 0.4218">
              <inertial pos="0.000126 0.018817 0.052939" quat="0.999996 -0.000955249 -0.00262397 -0.000580497" mass="1.82" diaginertia="0.00538697 0.00532442 0.00140982" />
              <joint name="head_pitch_joint" pos="0 0 0" axis="0 1 0" range="-0.5236 0.83775" actuatorfrcrange="-50 50" />
              <geom type="mesh" contype="0" conaffinity="0" group="1" density="0" rgba="0.7 0.7 0.7 1" mesh="head_pitch_link" />
              <body name="head_yaw_link" pos="0 0.0189 0.1335">
                <inertial pos="0.023654 -0.000734 0.042315" quat="0.667311 -0.227767 -0.231751 0.670156" mass="1.3" diaginertia="0.00535274 0.00472336 0.00378091" />
                <joint name="head_yaw_joint" pos="0 0 0" axis="0 0 1" range="-1.7453 1.7453" actuatorfrcrange="-50 50" />
                <geom type="mesh" contype="0" conaffinity="0" group="1" density="0" rgba="0.7 0.7 0.7 1" mesh="head_yaw_link" />
                <geom type="mesh" rgba="0.7 0.7 0.7 1" mesh="head_yaw_link" />
              </body>
            </body>
            <body name="left_shoulder_pitch_link" pos="0.0030848 0.11 0.36008" quat="0.990959 0.134164 0 0">
              <inertial pos="-0.0027817 0.050393 -0.023914" quat="0.959427 0.279803 0.00644957 0.0341716" mass="1.1927" diaginertia="0.00174925 0.00162902 0.000852428" />
              <joint name="left_shoulder_pitch_joint" pos="0 0 0" axis="0 1 0" range="-2.618 1.833" actuatorfrcrange="-130 130" />
              <geom type="mesh" contype="0" conaffinity="0" group="1" density="0" rgba="0.7 0.7 0.7 1" mesh="left_shoulder_pitch_link" />
              <geom type="mesh" rgba="0.7 0.7 0.7 1" mesh="left_shoulder_pitch_link" />
              <body name="left_shoulder_roll_link" pos="-0.0032074 0.059938 -0.039865" quat="0.990959 -0.134164 0 0">
                <inertial pos="-0.00126759 0.00399799 -0.0665267" quat="0.719226 0.0130341 -0.00543937 0.694633" mass="1.10983" diaginertia="0.00193836 0.00176489 0.00106378" />
                <joint name="left_shoulder_roll_joint" pos="0 0 0" axis="1 0 0" range="-0.517 2.494" actuatorfrcrange="-60 60" />
                <geom type="mesh" contype="0" conaffinity="0" group="1" density="0" rgba="0.7 0.7 0.7 1" mesh="left_shoulder_roll_link" />
                <geom type="mesh" rgba="0.7 0.7 0.7 1" mesh="left_shoulder_roll_link" />
                <body name="left_shoulder_yaw_link" pos="-0.0025601 0.0036752 -0.10421">
                  <inertial pos="0.00265957 0.0123454 -0.059622" quat="0.655577 0.0514587 -0.154929 0.737271" mass="0.352739" diaginertia="0.000897689 0.000854204 0.000287447" />
                  <joint name="left_shoulder_yaw_joint" pos="0 0 0" axis="0 0 1" range="-2.618 2.618" actuatorfrcrange="-60 60" />
                  <geom type="mesh" contype="0" conaffinity="0" group="1" density="0" rgba="0.7 0.7 0.7 1" mesh="left_shoulder_yaw_link" />
                  <geom type="mesh" rgba="0.7 0.7 0.7 1" mesh="left_shoulder_yaw_link" />
                  <body name="left_elbow_link" pos="0.016655 0.02211 -0.12792">
                    <inertial pos="0.0506767 -0.0216173 -0.00672238" quat="0.162352 0.731329 0.192833 0.633732" mass="1.70612" diaginertia="0.00522743 0.00521428 0.00111897" />
                    <joint name="left_elbow_joint" pos="0 0 0" axis="0 1 0" range="-0.986 3.071" actuatorfrcrange="-60 60" />
                    <geom type="mesh" contype="0" conaffinity="0" group="1" density="0" rgba="0.7 0.7 0.7 1" mesh="left_elbow_link" />
                    <geom type="mesh" rgba="0.7 0.7 0.7 1" mesh="left_elbow_link" />
                    <body name="left_wrist_roll_link" pos="0.13119 -0.021497 -0.013769">
                      <inertial pos="0.035915 -0.00154506 0.00012879" quat="0.349429 0.616315 -0.3656 0.603649" mass="0.77426" diaginertia="0.000715547 0.000661189 0.000632495" />
                      <joint name="left_wrist_roll_joint" pos="0 0 0" axis="1 0 0" range="-2.618 2.618" actuatorfrcrange="-60 60" />
                      <geom type="mesh" contype="0" conaffinity="0" group="1" density="0" rgba="0.7 0.7 0.7 1" mesh="left_wrist_roll_link" />
                      <body name="left_wrist_pitch_link" pos="0.037994 0.031144 0.00045104">
                        <inertial pos="0.0651093 -0.0317607 0.00235463" quat="0.491682 0.228754 0.718653 0.435268" mass="0.615258" diaginertia="0.000423535 0.000417983 0.000396162" />
                        <joint name="left_wrist_pitch_joint" pos="0 0 0" axis="0 1 0" range="-0.576 0.576" actuatorfrcrange="-10 10" />
                        <geom type="mesh" contype="0" conaffinity="0" group="1" density="0" rgba="0.7 0.7 0.7 1" mesh="left_wrist_pitch_link" />
                        <body name="left_wrist_yaw_link" pos="0.069283 -0.031045 -0.0006247">
                          <inertial pos="0.0479324 0.0322472 0.0143745" quat="-0.313045 0.629844 -0.0838475 0.705882" mass="0.616082" diaginertia="0.00131865 0.00121052 0.000840808" />
                          <joint name="left_wrist_yaw_joint" pos="0 0 0" axis="0 0 1" range="-1.22 1.22" actuatorfrcrange="-10 10" />
                          <geom type="mesh" contype="0" conaffinity="0" group="1" density="0" rgba="0.4 0.4 0.4 1" mesh="left_wrist_yaw_link" />
                          <geom type="mesh" rgba="0.4 0.4 0.4 1" mesh="left_wrist_yaw_link" />
                          <geom pos="0.0577152 0 -0.00014865" quat="1 0 0 0" type="mesh" contype="0" conaffinity="0" group="1" density="0" rgba="0.4 0.4 0.4 1" mesh="left_hand_link" />
                          <geom pos="0.0577152 0 -0.00014865" quat="1 0 0 0" type="mesh" rgba="0.4 0.4 0.4 1" mesh="left_hand_link" />
                        </body>
                      </body>
                    </body>
                  </body>
                </body>
              </body>
            </body>
            <body name="right_shoulder_pitch_link" pos="0.0030848 -0.11 0.36008" quat="0.990959 -0.134164 0 0">
              <inertial pos="-0.0027814 -0.050393 -0.023914" quat="0.959425 -0.279804 0.00643587 -0.0342398" mass="1.1927" diaginertia="0.00174925 0.00162902 0.000852428" />
              <joint name="right_shoulder_pitch_joint" pos="0 0 0" axis="0 1 0" range="-2.618 1.833" actuatorfrcrange="-130 130" />
              <geom type="mesh" contype="0" conaffinity="0" group="1" density="0" rgba="0.7 0.7 0.7 1" mesh="right_shoulder_pitch_link" />
              <geom type="mesh" rgba="0.7 0.7 0.7 1" mesh="right_shoulder_pitch_link" />
              <body name="right_shoulder_roll_link" pos="-0.0032074 -0.059938 -0.039865" quat="0.990959 0.134164 0 0">
                <inertial pos="-0.00126782 -0.0039981 -0.0665261" quat="0.694607 -0.0054503 0.0130148 0.719251" mass="1.10982" diaginertia="0.00193838 0.00176496 0.00106379" />
                <joint name="right_shoulder_roll_joint" pos="0 0 0" axis="1 0 0" range="-2.494 0.517" actuatorfrcrange="-60 60" />
                <geom type="mesh" contype="0" conaffinity="0" group="1" density="0" rgba="0.7 0.7 0.7 1" mesh="right_shoulder_roll_link" />
                <geom type="mesh" rgba="0.7 0.7 0.7 1" mesh="right_shoulder_roll_link" />
                <body name="right_shoulder_yaw_link" pos="-0.0025601 -0.0036752 -0.10421">
                  <inertial pos="0.00266059 -0.0123451 -0.0596234" quat="0.737262 -0.154921 0.0514524 0.65559" mass="0.352742" diaginertia="0.000897692 0.000854184 0.000287444" />
                  <joint name="right_shoulder_yaw_joint" pos="0 0 0" axis="0 0 1" range="-2.618 2.618" actuatorfrcrange="-60 60" />
                  <geom type="mesh" contype="0" conaffinity="0" group="1" density="0" rgba="0.7 0.7 0.7 1" mesh="right_shoulder_yaw_link" />
                  <geom type="mesh" rgba="0.7 0.7 0.7 1" mesh="right_shoulder_yaw_link" />
                  <body name="right_elbow_link" pos="0.016655 -0.02211 -0.12792">
                    <inertial pos="0.0506784 0.0216171 -0.00672338" quat="-0.1624 0.731318 -0.192894 0.633713" mass="1.70617" diaginertia="0.00522767 0.0052145 0.00111905" />
                    <joint name="right_elbow_joint" pos="0 0 0" axis="0 1 0" range="-0.986 3.071" actuatorfrcrange="-60 60" />
                    <geom type="mesh" contype="0" conaffinity="0" group="1" density="0" rgba="0.7 0.7 0.7 1" mesh="right_elbow_link" />
                    <geom type="mesh" rgba="0.7 0.7 0.7 1" mesh="right_elbow_link" />
                    <body name="right_wrist_roll_link" pos="0.13119 0.021497 -0.013769">
                      <inertial pos="0.0359137 0.00155865 0.00014187" quat="0.61587 0.348982 -0.602387 0.368844" mass="0.774265" diaginertia="0.00071595 0.000661595 0.000632525" />
                      <joint name="right_wrist_roll_joint" pos="0 0 0" axis="1 0 0" range="-2.618 2.618" actuatorfrcrange="-60 60" />
                      <geom type="mesh" contype="0" conaffinity="0" group="1" density="0" rgba="0.7 0.7 0.7 1" mesh="right_wrist_roll_link" />
                      <body name="right_wrist_pitch_link" pos="0.037994 -0.031144 0.00045104">
                        <inertial pos="0.0651131 0.0317523 0.00231986" quat="0.440426 0.716762 0.242507 0.483185" mass="0.615837" diaginertia="0.000424256 0.000418373 0.000396861" />
                        <joint name="right_wrist_pitch_joint" pos="0 0 0" axis="0 1 0" range="-0.576 0.576" actuatorfrcrange="-10 10" />
                        <geom type="mesh" contype="0" conaffinity="0" group="1" density="0" rgba="0.7 0.7 0.7 1" mesh="right_wrist_pitch_link" />
                        <body name="right_wrist_yaw_link" pos="0.069283 0.031045 -0.0006247">
                          <inertial pos="0.0337013 0.0421432 -0.0074833" quat="-0.16511 0.651316 0.385961 0.632108" mass="0.616082" diaginertia="0.00139743 0.00124795 0.000903596" />
                          <joint name="right_wrist_yaw_joint" pos="0 0 0" axis="0 0 1" range="-1.22 1.22" actuatorfrcrange="-10 10" />
                          <geom type="mesh" contype="0" conaffinity="0" group="1" density="0" rgba="0.4 0.4 0.4 1" mesh="right_wrist_yaw_link" />
                          <geom type="mesh" rgba="0.4 0.4 0.4 1" mesh="right_wrist_yaw_link" />
                          <geom pos="0.0582412 0 -0.00017221" quat="1 0 0 0" type="mesh" contype="0" conaffinity="0" group="1" density="0" rgba="0.4 0.4 0.4 1" mesh="right_hand_link" />
                          <geom pos="0.0582412 0 -0.00017221" quat="1 0 0 0" type="mesh" rgba="0.4 0.4 0.4 1" mesh="right_hand_link" />
                        </body>
                      </body>
                    </body>
                  </body>
                </body>
              </body>
            </body>
            <body name="torso_constraint_R_link" pos="0.019493 -0.04025 0.053396" quat="0.999945 0.00937926 -0.00475762 4.46254e-05">
              <inertial pos="0.0159495 -0.000785253 0.00079341" quat="0.602878 0.794092 0.0748794 0.0186933" mass="0.0469149" diaginertia="1.87702e-05 1.53865e-05 1.2808e-05" />
              <joint name="torso_constraint_R_joint" pos="0 0 0" axis="1 0 0" range="-0.64577 0.87267" />
              <geom type="mesh" contype="0" conaffinity="0" group="1" density="0" rgba="1 1 0 1" mesh="Link-pitch-R-A3" />
              <geom size="0.005" pos="0.0168 0.0254492 -0.00160815" contype="0" conaffinity="0" group="1" density="0" rgba="0 0 1 1" />
              <body name="right_waist_loop_rod" pos="0.0168 0.0254492410032358 -0.00160814562793653">
                <inertial pos="0 0 0" mass="0.001" diaginertia="1e-7 1e-7 1e-7" />
                <joint name="right_waist_loop_rod_joint" type="ball" damping="0.1" />
                <geom type="capsule" fromto="0 0 0 -0.000487088004 -0.0101668378 -0.0637550256" size="0.003" contype="0" conaffinity="0" group="1" density="0" rgba="0.1 0.1 0.1 0.5" />
              </body>
            </body>
            <body name="torso_constraint_L_link" pos="0.019493 0.04025 0.053396" quat="0.999945 0.00937926 -0.00475762 4.46254e-05">
              <inertial pos="0.0158404 0.000561908 -0.000136558" quat="0.683869 0.727072 -0.0431726 -0.0427316" mass="0.0473978" diaginertia="1.8835e-05 1.58067e-05 1.26334e-05" />
              <joint name="torso_constraint_L_joint" pos="0 0 0" axis="1 0 0" range="-0.64577 0.87267" />
              <geom type="mesh" contype="0" conaffinity="0" group="1" density="0" rgba="0.792157 0.819608 0.933333 1" mesh="Link-pitch-L-A3" />
              <geom size="0.005" pos="0.0168 -0.0254993 0.000182946" contype="0" conaffinity="0" group="1" density="0" rgba="0 1 0 1" />
              <body name="left_waist_loop_rod" pos="0.0168 -0.0254993437309805 0.000182946139840212">
                <inertial pos="0 0 0" mass="0.001" diaginertia="1e-7 1e-7 1e-7" />
                <joint name="left_waist_loop_rod_joint" type="ball" damping="0.1" />
                <geom type="capsule" fromto="0 0 0 -0.000824985637 0.00828633806 -0.0649331479" size="0.003" contype="0" conaffinity="0" group="1" density="0" rgba="0.1 0.1 0.1 0.5" />
              </body>
            </body>
          </body>
        </body>
      </body>
    </body>
  </worldbody>
  <!-- Six closed-loop rods: ankle, knee, and waist on both sides. -->
  <equality>
    <connect name="left_ankle_connect" body1="left_ankle_pitch_link" body2="left_ankle_loop_rod" anchor="-0.04003 0.0373 0.0073" />
    <connect name="right_ankle_connect" body1="right_ankle_pitch_link" body2="right_ankle_loop_rod" anchor="-0.04003 -0.0373 0.0073" />
    <connect name="left_knee_connect" body1="left_knee_link" body2="left_knee_loop_rod" anchor="0.014618 0 0.031799" />
    <connect name="right_knee_connect" body1="right_knee_link" body2="right_knee_loop_rod" anchor="0.014618 0 0.031799" />
    <connect name="right_waist_connect" body1="waist_yaw_link" body2="right_waist_loop_rod" anchor="0.0364243031713012 -0.0237442098797672 0.0209891671028344" />
    <connect name="left_waist_connect" body1="waist_yaw_link" body2="left_waist_loop_rod" anchor="0.0360863892837352 0.0242546006700213 0.0209892676099125" />
  </equality>
  <!-- Motors exclude the passive knee, ankle-pitch, waist-roll, and waist-pitch joints. -->
  <actuator>
    <motor name="left_hip_pitch_joint" joint="left_hip_pitch_joint" ctrlrange="-360 360" />
    <motor name="left_hip_roll_joint" joint="left_hip_roll_joint" ctrlrange="-360 360" />
    <motor name="left_hip_yaw_joint" joint="left_hip_yaw_joint" ctrlrange="-360 360" />
    <motor name="left_ankle_roll_joint" joint="left_ankle_roll_joint" ctrlrange="-19 19" />
    <motor name="left_ankle_A_joint" joint="left_ankle_A_joint" ctrlrange="-105.6 105.6" />
    <motor name="left_knee_motor_joint" joint="left_knee_motor_joint" ctrlrange="-360 360" />
    <motor name="right_hip_pitch_joint" joint="right_hip_pitch_joint" ctrlrange="-360 360" />
    <motor name="right_hip_roll_joint" joint="right_hip_roll_joint" ctrlrange="-360 360" />
    <motor name="right_hip_yaw_joint" joint="right_hip_yaw_joint" ctrlrange="-360 360" />
    <motor name="right_ankle_roll_joint" joint="right_ankle_roll_joint" ctrlrange="-19 19" />
    <motor name="right_ankle_A_joint" joint="right_ankle_A_joint" ctrlrange="-105.6 105.6" />
    <motor name="right_knee_motor_joint" joint="right_knee_motor_joint" ctrlrange="-360 360" />
    <motor name="waist_yaw_joint" joint="waist_yaw_joint" ctrlrange="-120 120" />
    <motor name="head_pitch_joint" joint="head_pitch_joint" ctrlrange="-50 50" />
    <motor name="head_yaw_joint" joint="head_yaw_joint" ctrlrange="-50 50" />
    <motor name="left_shoulder_pitch_joint" joint="left_shoulder_pitch_joint" ctrlrange="-130 130" />
    <motor name="left_shoulder_roll_joint" joint="left_shoulder_roll_joint" ctrlrange="-60 60" />
    <motor name="left_shoulder_yaw_joint" joint="left_shoulder_yaw_joint" ctrlrange="-60 60" />
    <motor name="left_elbow_joint" joint="left_elbow_joint" ctrlrange="-60 60" />
    <motor name="left_wrist_roll_joint" joint="left_wrist_roll_joint" ctrlrange="-60 60" />
    <motor name="left_wrist_pitch_joint" joint="left_wrist_pitch_joint" ctrlrange="-10 10" />
    <motor name="left_wrist_yaw_joint" joint="left_wrist_yaw_joint" ctrlrange="-10 10" />
    <motor name="right_shoulder_pitch_joint" joint="right_shoulder_pitch_joint" ctrlrange="-130 130" />
    <motor name="right_shoulder_roll_joint" joint="right_shoulder_roll_joint" ctrlrange="-60 60" />
    <motor name="right_shoulder_yaw_joint" joint="right_shoulder_yaw_joint" ctrlrange="-60 60" />
    <motor name="right_elbow_joint" joint="right_elbow_joint" ctrlrange="-60 60" />
    <motor name="right_wrist_roll_joint" joint="right_wrist_roll_joint" ctrlrange="-60 60" />
    <motor name="right_wrist_pitch_joint" joint="right_wrist_pitch_joint" ctrlrange="-10 10" />
    <motor name="right_wrist_yaw_joint" joint="right_wrist_yaw_joint" ctrlrange="-10 10" />
    <motor name="torso_constraint_R_joint" joint="torso_constraint_R_joint" ctrlrange="-90 90" />
    <motor name="torso_constraint_L_joint" joint="torso_constraint_L_joint" ctrlrange="-90 90" />
  </actuator>
  <!-- setup scene -->
  <statistic center="1.0 0.7 1.0" extent="0.8" />
  <visual>
    <headlight diffuse="0.6 0.6 0.6" ambient="0.1 0.1 0.1" specular="0.9 0.9 0.9" />
    <rgba haze="0.15 0.25 0.35 1" />
    <global azimuth="-140" elevation="-20" />
  </visual>
  <asset>
    <texture type="skybox" builtin="flat" rgb1="0 0 0" rgb2="0 0 0" width="512" height="3072" />
    <texture type="2d" name="groundplane" builtin="checker" mark="edge" rgb1="0.2 0.3 0.4" rgb2="0.1 0.2 0.3" markrgb="0.8 0.8 0.8" width="300" height="300" />
    <material name="groundplane" texture="groundplane" texuniform="true" texrepeat="5 5" reflectance="0.2" />
  </asset>
  <worldbody>
    <light pos="1 0 3.5" dir="0 0 -1" directional="true" />
    <geom name="floor" size="0 0 0.05" type="plane" material="groundplane" />
  </worldbody>
</mujoco>
